<?xml version="1.0" ?>
<!-- =================================================================================== -->
<!-- |    This document was autogenerated by xacro from /opt/ros/kinetic/share/moveit_resources/panda_description/urdf/panda.urdf | -->
<!-- |    EDITING THIS FILE BY HAND IS NOT RECOMMENDED                                 | -->
<!-- =================================================================================== -->
<robot name="rail_gripper" xmlns:xacro="http://www.ros.org/wiki/xacro">
        <link name="world">
    
  </link>

    <link name="base">
    <visual>
      <geometry>
        <box size="0.0 0.0 0.0"/>
      </geometry>
      <origin xyz="0 0 0"/>
      <material name="blue">
        <color rgba="0 0 .8 1"/>
      </material>
    </visual>
    
  </link>

  <link name="base2">
    <visual>
      <geometry>
        <box size="0.0 0.0 0.0"/>
      </geometry>
      <origin xyz="0 0 0"/>
      <material name="red">
        <color rgba=" 1 .8 0"/>
      </material>
    </visual>
    
  </link>


  <joint name="slider_to_base_x" type="prismatic">
    <axis xyz="1 0 0"/>
    <origin xyz="0.0 0.0 0.0"/>
    <parent link="world"/>
    <child link="base"/>
    <limit effort="1000.0" lower="-15" upper="15" velocity="5"/>
  </joint>

  <joint name="slider_to_base_z" type="prismatic">
    <axis xyz="0 0 1"/>
    <origin xyz="0.0 0.0 0.1"/>
    <parent link="base"/>
    <child link="base2"/>
    <limit effort="1000.0" lower="-15" upper="15" velocity="5"/>
  </joint>

  
    
    <joint name="panda_hand_joint" type="fixed">
        <parent link="base2" />
        <child link="panda_hand" />
        <!--origin rpy="0 0 -0.785398163397" xyz="0 0 0." /-->
        <origin rpy="1.57079632679 0 1.57079632679" xyz="0 0 0.8" />
    </joint>
    <link name="panda_hand">
        <visual>
            <geometry>
                <mesh filename="meshes/visual/hand.dae" />
            </geometry>
        </visual>
        <collision>
            <geometry>
                <mesh filename="meshes/collision/hand.stl" />
            </geometry>
        </collision>
        <inertial>
            <mass value="0.73"/>
            <origin xyz="0 0 0"/>
            <inertia ixx="1" ixy="0.0" ixz="0.0" iyy="1" iyz="0.0" izz="1"/>
        </inertial>
    </link>
    <link name="panda_leftfinger">
        <visual>
            <geometry>
                <mesh filename="meshes/visual/finger.dae" />
            </geometry>
        </visual>
        <collision>
            <geometry>
                <mesh filename="meshes/collision/finger.stl" />
            </geometry>
        </collision>
        <inertial>
            <mass value="0.1"/>
            <origin xyz="0 0 0"/>
            <inertia ixx="1" ixy="0.0" ixz="0.0" iyy="1" iyz="0.0" izz="1"/>
        </inertial>
    </link>
    <link name="panda_rightfinger">
        <visual>
            <origin rpy="0 0 3.14159265359" xyz="0 0 0" />
            <geometry>
                <mesh filename="meshes/visual/finger.dae" />
            </geometry>
        </visual>
        <collision>
            <origin rpy="0 0 3.14159265359" xyz="0 0 0" />
            <geometry>
                <mesh filename="meshes/collision/finger.stl" />
            </geometry>
        </collision>
        <inertial>
            <mass value="0.1"/>
            <origin xyz="0 0 0"/>
            <inertia ixx="1" ixy="0.0" ixz="0.0" iyy="1" iyz="0.0" izz="1"/>
        </inertial>
    </link>
    <joint name="panda_finger_joint1" type="prismatic">
        <parent link="panda_hand" />
        <child link="panda_leftfinger" />
        <origin rpy="0 0 0" xyz="0 0 0.0584" />
        <axis xyz="0 1 0" />
        <limit effort="20" lower="0.0" upper="0.04" velocity="0.2" />
    </joint>
    <joint name="panda_finger_joint2" type="prismatic">
        <parent link="panda_hand" />
        <child link="panda_rightfinger" />
        <origin rpy="0 0 0" xyz="0 0 0.0584" />
        <axis xyz="0 -1 0" />
        <limit effort="20" lower="0.0" upper="0.04" velocity="0.2" />
        <mimic joint="panda_finger_joint1" />
    </joint>
    <link name="panda_fingercenter">
        <inertial>
            <mass value="0"/>
            <origin xyz="0 0 0"/>
            <inertia ixx="1" ixy="0.0" ixz="0.0" iyy="1" iyz="0.0" izz="1"/>
        </inertial>
    </link>
    <joint name="panda_fingercenter_joint" type="fixed">
        <parent link="panda_hand" />
        <child link="panda_fingercenter" />
        <origin rpy="0 0 0" xyz="0 0 0.1025" />
        <axis xyz="0 0 0" />
    </joint>
</robot>
